Workbook

Sheet Sheet1
A1: csku | B1: cnombre | C1: cmarca | D1: cdescripcion | E1: cespecificaciones | F1: cimagen | G1: bestatus | H1: tcreate_at | I1: tupdate_at
A2: 00-0614-00-8 | B2: Cafetera Koblenz CKM-1350 en Color Negro con Acero Inoxidable Prepara Café Espresso Capiccino y Late 1350 Watts | C2: KOBLENZ | D2: Cafetera Koblenz CKM-1350 en Color Negro con Acero Inoxidable Prepara Café Espresso Capiccino y Late 1350 Watts | G2: t | H2: 46085.479 | I2: 46085.479
A3: 00-1522-00-2 | B3: Regulador Koblenz RI-20 1900VA / 1400W Entrada 120V Salida 108 - 132V 1 Salida | C3: KOBLENZ | D3: Regulador Koblenz RI-20 1900VA / 1400W Entrada 120V Salida 108 - 132V 1 Salida | E3: [{'grupo': 'Características Generales:', 'caracteristicas': [{'texto': 'Marca:', 'valor': 'Koblenz'}, {'texto': 'Artículo:', 'valor': 'Regulador'}, {'texto': 'Modelo:', 'valor': 'RI-20 C'}, {'texto': 'Color:', 'valor': 'Negro'}, {'texto': 'Capacidad:', 'valor': '1900 VA / 1400 W'}, {'texto': 'Voltaje de entrada:', 'valor': '120 VCA (operación 90–145 VCA)'}, {'texto': 'Voltaje de salida:', 'valor': '108–132 VCA'}, {'texto': 'Frecuencia:', 'valor': '60 Hz'}, {'texto': 'Salidas:', 'valor': '1 contacto aterrizado y regulado'}, {'texto': 'Protección:', 'valor': 'Autodesconexión arriba de 150 VCA y debajo de 60 VCA, disyuntor térmico 25 A'}, {'texto': 'Indicadores:', 'valor': '2 LEDs (Encendido y Desconexión automática)'}, {'texto': 'Dimensiones sin empaque:', 'valor': '14 × 12 × 19 cm'}, {'texto': 'Peso sin empaque:', 'valor': '3.2 kg'}, {'texto': 'Dimensiones con empaque:', 'valor': '19 × 16 × 22 cm'}, {'texto': 'Peso con empaque:', 'valor': '3.5 kg'}, {'texto': 'Garantía:', 'valor': '5 años'}]}] | F3: ['https://contenidos.exel.com.mx/ImagenesProductos/KB/KBCREUAB042_zoom.png', 'https://contenidos.exel.com.mx/ImagenesProductos/KB/KBCREUAB042_2_zoom.png'] | G3: t | H3: 46085.479 | I3: 46085.479
A4: 00-1560-2 | B4: Regulador Koblenz ER-2550 2500VA/2000W 6 Contactos | C4: KOBLENZ | D4: Protegen la vida de sus aparatos electrónicos y son ideales para el respaldo de equipos de cómputo y oficina. Supresor de picos integrado y fusible de extra protección. Protección de línea telefónica contra descargas atmosféricas. | E4: [{'grupo': 'Características Generales:', 'caracteristicas': [{'texto': 'Marca:', 'valor': 'Koblenz'}, {'texto': 'Artículo:', 'valor': 'Regulador'}, {'texto': 'Modelo:', 'valor': 'ER-2550'}, {'texto': 'Salida:', 'valor': 'Tensión nominal 120V~ ±10% | Sobrecarga 120% durante 1 Hora Máximo'}, {'texto': 'Entrada:', 'valor': 'Capacidad 2,500 VA / 2,000 W | Tensión nominal 120 V | Rango de regulación 95 - 145 V'}, {'texto': 'Sistema:', 'valor': 'Monofásico con tierra física'}, {'texto': 'Protecciones:', 'valor': 'Fusible de 20 A para sobrecargas y/o corto circuito'}, {'texto': 'Contactos:', 'valor': '6, (6) NEMA5-15R'}, {'texto': 'Interruptor:', 'valor': 'Encendido/apagado de uso rudo'}, {'texto': 'Dimensiones:', 'valor': '19.5 cm x 11 cm x 11 cm'}]}] | F4: ['https://contenidos.exel.com.mx/ImagenesProductos/KBCREUAB002_zoom.jpg', 'https://contenidos.exel.com.mx/ImagenesProductos/KBCREUAB002_2_zoom.jpg'] | G4: t | H4: 46085.479 | I4: 46085.479
A5: 00-1588-3 | B5: Regulador Koblenz ER-2250 2250VA/1000W 8 Contactos 1LED Garantía 5 Años | C5: KOBLENZ | D5: Regulador Koblenz ER-2250 2250VA/1000W 8 Contactos 1LED Garantía 5 Años | E5: [{'grupo': 'Características Generales:', 'caracteristicas': [{'texto': 'Marca:', 'valor': 'Koblenz'}, {'texto': 'Artículo:', 'valor': 'Regulador'}, {'texto': 'Modelo:', 'valor': 'ER-2250'}, {'texto': 'Tensión nominal(Salida):', 'valor': '120 V~ ±10%'}, {'texto': 'Sobrecarga:', 'valor': '120% durante 1 Hr máximo 200% durante 20 seg máximo'}, {'texto': 'Supresor de picos:', 'valor': '134 Joules'}, {'texto': 'Capacidad(entrada):', 'valor': '2250 VA / 1 000 W'}, {'texto': 'Tensión nominal(entrada):', 'valor': '120 V'}, {'texto': 'Rango de regulación:', 'valor': '95 - 145 V'}, {'texto': 'Corriente máxima:', 'valor': ' 8.3 A'}, {'texto': 'Frecuencia:', 'valor': '60 Hz ±3%'}, {'texto': 'Sistema:', 'valor': 'Monofásico con tierra física'}, {'texto': 'Protecciones:', 'valor': 'Disyuntor térmico'}, {'texto': 'Contactos:', 'valor': '(8) NEMA5-15R aterrizados regulados'}, {'texto': 'Indicadores visuales:', 'valor': '1 LED (Azul: encendido / LED flasheando: desconexión)'}, {'texto': 'Dimensiones:', 'valor': '19.4 cm x 11 cm x 10 cm sin caja | 22.5 cm x 11.5 cm x 10.6 cm con caja'}, {'texto': 'Peso:', 'valor': '1.62 Kg | 1.72 Kg'}]}] | F5: ['https://contenidos.exel.com.mx/ImagenesProductos/KBCREUAB025_zoom.jpg', 'https://contenidos.exel.com.mx/ImagenesProductos/KBCREUAB025_2_zoom.jpg'] | G5: t | H5: 46085.479 | I5: 46085.479
A6: 00-1596-00-6 | B6: Regulador Koblenz RI-2002 2000VA/1500W 1 Contacto | C6: KOBLENZ | D6: Regulador Koblenz RI-2002 2000VA/1500W 1 Contacto | E6: [{'grupo': 'Características Generales:', 'caracteristicas': [{'texto': 'Marca:', 'valor': 'Koblenz'}, {'texto': 'Artículo:', 'valor': 'Regulador '}, {'texto': 'Modelo:', 'valor': 'RI-2002'}, {'texto': 'Capacidad:', 'valor': '2000VA/1500W'}, {'texto': 'Contactos:', 'valor': 'aterrizados regulados (1) '}, {'texto': 'Uso:', 'valor': 'Refrigeradores 24-28 pies cúbicos, refresqueros, vitrinas, lavadoras, secadoras, microondas'}, {'texto': 'Dimensiones:', 'valor': '22 cm x 19 cm x 16 cm'}, {'texto': 'Peso:', 'valor': '4 kg'}]}] | F6: ['https://contenidos.exel.com.mx/ImagenesProductos/KBCREUAB029_zoom.jpg'] | G6: t | H6: 46085.479 | I6: 46085.479
A7: 00-1599-00-0 | B7: Regulador Koblenz RS-1410 1410VA/700W Switch 8 Contactos | C7: KOBLENZ | D7: Regulador Koblenz RS-1410 1410VA/700W Switch 8 Contactos | E7: [{'grupo': 'Características Generales:', 'caracteristicas': [{'texto': 'Marca:', 'valor': 'Koblenz'}, {'texto': 'Artículo:', 'valor': 'Regulador '}, {'texto': 'Modelo:', 'valor': 'RS-1410'}, {'texto': 'Capacidad:', 'valor': '1410 VA / 700 W'}, {'texto': 'Contactos:', 'valor': '8 contactos regulados aterrizados'}, {'texto': 'Desconexión:', 'valor': 'en alto voltaje '}, {'texto': 'Uso:', 'valor': 'Ideal para Hogar u Oficina'}, {'texto': 'Diseño:', 'valor': 'Moderno diseño con contactos en la parte superior y gabinete de plástico.'}, {'texto': 'Interruptor:', 'valor': 'de encendido/apagado de uso rudo y switch térmico protector. '}, {'texto': 'Regulación:', 'valor': '3 Pasos'}, {'texto': 'Switch:', 'valor': '8A'}, {'texto': 'Rango de tensión de salida: ', 'valor': '108 - 132 V~'}, {'texto': 'Luz:', 'valor': "2 LED's (encendido y regulando)"}, {'texto': ' Longitud Cable: ', 'valor': '1m'}, {'texto': 'Garantía:', 'valor': '2 años'}, {'texto': 'Dimensiones:', 'valor': '17.7 cm x 11.6 cm x 9.8 cm'}, {'texto': 'Peso:', 'valor': '1.214 kg'}]}] | F7: ['https://contenidos.exel.com.mx/ImagenesProductos/KBCREUAB030_zoom.jpg'] | G7: t | H7: 46085.479 | I7: 46085.479
A8: 00-3121-00-1 | B8: Horno Freidora Koblenz HFKM-1400 de Acero Inoxidable 1400 Watts 4 Programas de Cocción | C8: KOBLENZ | D8: Horno Freidora Koblenz HFKM-1400 de Acero Inoxidable 1400 Watts 4 Programas de Cocción | G8: t | H8: 46085.479 | I8: 46085.479
A9: 00-4196-2 | B9: UPS Koblenz 20012 USB/R Línea Pro 2KVA/1200W 8 Contactos 6 LEDS | C9: KOBLENZ | D9: Excelente microprocesador que garantiza una excelente fiabilidad. Ideal para la protección de equipos de escritorio. Auto reinicio mientras se recupera la corriente. | E9: [{'grupo': 'Características Generales:', 'caracteristicas': [{'texto': 'Marca:', 'valor': 'Koblenz'}, {'texto': 'Artículo:', 'valor': 'UPS'}, {'texto': 'Modelo:', 'valor': '20012 USB/R'}, {'texto': 'Tipo:', 'valor': 'Interactivo con regulador de voltaje integrado'}, {'texto': 'Capacidad:', 'valor': 'Potencia 2000 VA/ 1200 W'}, {'texto': 'Fase Monofásica:', 'valor': '120V'}, {'texto': 'Topología:', 'valor': 'onda cuasisenoidal'}, {'texto': 'Arranque:', 'valor': 'en frío Soportado'}, {'texto': 'Tensión de salida nominal:', 'valor': '120Vca ± 10%'}, {'texto': 'Frecuencia de salida:', 'valor': '50/60 Hz'}, {'texto': 'Conexiones de salida:', 'valor': '(6) NEMA 5-15R con protección de batería y (2) NEMA 5-15R con supresión de picos'}, {'texto': 'Capacidad de sobrecarga:', 'valor': '(con tensión de línea) 25%'}, {'texto': 'Voltaje de Entrada:', 'valor': '120 V'}, {'texto': 'Rango de Voltaje:', 'valor': '89 - 145 Vca'}, {'texto': 'Frecuencia de Entrada:', 'valor': '60 Hz ± 5%'}, {'texto': 'Tipo de Clavija:', 'valor': 'NEMA 5-15P'}, {'texto': 'Longitud del Cable:', 'valor': '1.8m'}, {'texto': 'Tipo de Batería:', 'valor': 'VRLA batería sellada de plomo ácido libre de mantenimiento a prueba de filtración'}, {'texto': 'Baterías Pre-Instaladas:', 'valor': '(2) 12V 9Ah'}, {'texto': 'Panel Control LED:', 'valor': 'odo AC - (En línea) modo batería, batería baja, sobrecarga, reemplazo de batería'}, {'texto': 'Supresión de Pico:', 'valor': '316 Joules'}, {'texto': 'Dimensiones:', 'valor': '39.7 cm x 20.5 cm x 14.6 cm'}, {'texto': 'Peso:', 'valor': '11.5 kg'}]}] | F9: ['https://contenidos.exel.com.mx/ImagenesProductos/KBCREUAB024_zoom.jpg'] | G9: t | H9: 46085.479 | I9: 46085.479
A10: 00-4206-9 | B10: Regulador Koblenz 7016 NoBreak USB/R 700VA/360W Respaldo 25 Minutos 6 Contactos Garantía 3 Años | C10: KOBLENZ | D10: Construido con cargador inteligente que reduce hasta 50% el tiempo de carga. Regulador de voltaje integrado (altos y bajos) que permite la estabilización del voltaje, 6 contactos NEMA 5-15R. | E10: [{'grupo': 'Características Generales:', 'caracteristicas': [{'texto': 'Marca:', 'valor': 'Koblenz'}, {'texto': 'Artículo:', 'valor': 'Regulador/UPS'}, {'texto': 'Modelo:', 'valor': '7016 USB/R'}, {'texto': 'Salida:', 'valor': 'Capacidad potencia 700 VA / 360 W | Tensión de salida nominal 120V distorsión ±10%'}, {'texto': 'Fase:', 'valor': 'Monofásica 120 V'}, {'texto': 'Topología:', 'valor': 'Linea interactiva'}, {'texto': 'Frecuencia de salida en modo batería:', 'valor': '60 Hz ±1 Hz'}, {'texto': 'Tipo de forma de onda:', 'valor': 'Senoidal simulada'}, {'texto': 'Conexiones de salida:', 'valor': '(4) NEMA 5-15R con protección de batería OPCIÓN A: (3) NEMA 5-15R con protección de batería | (2) NEMA 5-15R sin protección de batería OPCIÓN A: (3) NEMA 5-15R sin protección de batería'}, {'texto': 'Entrada:', 'valor': 'Voltaje 120 V | Rango de voltaje 90 - 145 Vca | Frecuencia de entrada 60 Hz / 50 Hz'}, {'texto': 'Tipo de enchufe:', 'valor': 'NEMA 5-15P'}, {'texto': 'Longitud del cable:', 'valor': '1.5 metros (fijo) integrado al equipo'}, {'texto': 'Tipo de batería:', 'valor': 'Batería sellada de plomo ácido libre de mantenimiento a prueba de filtración'}, {'texto': 'Baterías pre-instaladas:', 'valor': '(1) 12V 7Ah'}, {'texto': 'Tiempo recarga:', 'valor': '4 horas al 90%'}, {'texto': 'Puerto de interfaz:', 'valor': 'USB'}, {'texto': 'Panel control:', 'valor': '(3) LED indicadores - en línea, en batería, falla'}, {'texto': 'Protección:', 'valor': 'Supresión de picos - 365 Joules y protector térmico contra sobrecargas | RJ-11 (2)'}, {'texto': 'Dimensiones:', 'valor': '28.9 cm 14.2 cm x 9.7 cm'}]}] | F10: ['https://contenidos.exel.com.mx/ImagenesProductos/KBCREUAB005_zoom.jpg', 'https://contenidos.exel.com.mx/ImagenesProductos/KBCREUAB005_2_zoom.jpg'] | G10: t | H10: 46085.479 | I10: 46085.479
A11: 00-4226-7 | B11: UPS Koblenz 15012 USB/RN Línea Pro 1.5 KVA/900W 8 Contactos 6 LEDS | C11: KOBLENZ | D11: Cargador de baterías inteligente integrado que reduce hasta en un 50% el tiempo de carga. Excelente microprocesador que garantiza una excelente fiabilidad. Ideal para la protección de equipos de escritorio | G11: t | H11: 46085.479 | I11: 46085.479
A12: 00-4231-7 | B12: UPS Koblenz One Line Doble Conversión 30015 OL USB/R 3KVA/2700W 2 y 1 Contactos Senoidal Pura | C12: KOBLENZ | D12: UPS on line de doble conversión ideal para el respaldo de aplicaciones críticas de voz, datos, redes, servidores, sistemas de seguridad y sistemas de fabricación. Su tiempo de transferencia cero garantiza el funcionamiento continuo durante cortes de corriente, fluctuaciones de voltaje y sobretensiones. Salida de onda senoidal pura que garantiza la compatibilidad con cualquier equipo. Función ECO que permite la disminución de la producción de calor y el ahorro en costos de energía. | G12: t | H12: 46085.479 | I12: 46085.479
A13: 00-4233-3 | B13: Regulador Koblenz 10017 NoBreak USB/R 1000VA/500 Respaldo 60 Minutos 8 Contactos Garantía 3 Años | C13: KOBLENZ | D13: Excelente microprocesador de control que garantiza una alta fiabilidad. Regulador de voltaje de 4 pasos (2 Boost, 1 Buck, 1 Neutro) que permite la estabilización del voltaje | E13: [{'grupo': 'Características Generales:', 'caracteristicas': [{'texto': 'Marca:', 'valor': 'Koblenz'}, {'texto': 'Artículo:', 'valor': 'Regulador/UPS'}, {'texto': 'Modelo:', 'valor': '10017 USB/R'}, {'texto': 'Capacidad potencia:', 'valor': '1,000 VA/ 500 W'}, {'texto': 'Fase:', 'valor': 'Monofásica 120 V'}, {'texto': 'Topología:', 'valor': 'Línea interactiva onda cuasisenoidal'}, {'texto': 'Salida:', 'valor': 'Tensión de salida nominal 120V ± 10% | Frecuencia de salida en modo batería 60 Hz ± 1 Hz'}, {'texto': 'Tipo de forma de onda:', 'valor': 'Cuasisenoidal'}, {'texto': 'Conexiones de salida:', 'valor': '(4) NEMA 5-15R con protección de batería | (4) NEMA 5-15R con supresión de picos'}, {'texto': 'Entrada:', 'valor': 'Voltaje 120 V | Rango de voltaje 85-145 Vca | Frecuencia de entrada 60 Hz ± 5Hz'}, {'texto': 'Tipo de clavija:', 'valor': 'NEMA 5-15P'}, {'texto': 'Longitud del cable:', 'valor': '1.8 metros'}, {'texto': 'Tipo de batería:', 'valor': 'VRLA batería sellada de plomo ácido libre de mantenimiento a prueba de filtración'}, {'texto': 'Baterías pre-instaladas:', 'valor': '12V 9Ah'}, {'texto': 'Tiempo recarga:', 'valor': '4-8 horas al 90%'}, {'texto': 'Puerto de interfaz:', 'valor': 'USB'}, {'texto': 'Panel de control:', 'valor': 'LED: modo AC (en línea), modo batería, batería baja, sobrecarga, reemplazo batería'}, {'texto': 'Protección:', 'valor': 'Supresión de picos - 450 Joules | RJ11'}, {'texto': 'Ambiente operativo:', 'valor': '0-90% RH. 0 - 40 ºC sin condensación'}]}] | F13: ['https://contenidos.exel.com.mx/ImagenesProductos/KBCREUAB007_zoom.jpg'] | G13: t | H13: 46085.479 | I13: 46085.479
A14: 00-4235-00-8 | B14: UPS Koblenz One Line Doble Conversión 60019 OL 2 P 6KVA/6000W Bifásico Senoidal Pura | C14: KOBLENZ | D14: UPS on line de doble conversión ideal para el respaldo de aplicaciones críticas de voz, datos, redes, servidores, sistemas de seguridad y sistemas de fabricación. Tecnología de DSP que garantiza un alto rendimiento.Factor de potencia 1. Comunicación SNMP / USB / RS - 232. | G14: t | H14: 46085.479 | I14: 46085.479
A15: 00-4237-00-4 | B15: UPS Koblenz No Break Interactivo 15007 USB/R Onda Cuasisenoidal 1500VA/900W 7 Contactos | C15: KOBLENZ | D15: UPS línea Interactiva con regulador de voltaje integrado, ideal para la protección de equipos de escritorio. Protección para teléfono, fax modem RJ-11 y cable coaxial RG6. Protección contra sobre carga a través de un indicador visual y alarma audible. Regulador de voltaje integrado (altos y bajos) que permite la estabilización del voltaje. | G15: t | H15: 46085.479 | I15: 46085.479
A16: 00-4239-00-0 | B16: UPS Koblenz One Line Doble Conversión 20015 OL USB/R 2KVA/1600W 8 Contactos Senoidal Pura | C16: KOBLENZ | D16: UPS on line de doble conversión ideal para el respaldo de aplicaciones críticas de voz, datos, redes, servidores, sistemas de seguridad y sistemas de fabricación. Su tiempo de transferencia cero garantiza el funcionamiento continuo durante cortes de corriente, fluctuaciones de voltaje y sobretensiones. Salida de onda senoidal pura que garantiza la compatibilidad con cualquier equipo. Función ECO que permite la disminución de la producción de calor y el ahorro en costos de energía. | G16: t | H16: 46085.479 | I16: 46085.479
A17: 00-4240-00-8 | B17: UPS Koblenz Online Doble Conversión 10KVA/10000W Ideal para Respaldo de Aplicaciones Críticas | C17: KOBLENZ | D17: UPS Koblenz Online Doble Conversión 10KVA/10000W Ideal para Respaldo de Aplicaciones Críticas | G17: t | H17: 46085.479 | I17: 46085.479
A18: 00-4241-00-6 | B18: Regulador Koblenz 5216 R NoBreak 520VA/240W 6 Contactos | C18: KOBLENZ | D18: Protección para teléfono y fax modem RJ-1, 6 contactos NEMA 5-15R. Excelente microprocesador de control que garantiza una alta fiabilidad | E18: [{'grupo': 'Características Generales:', 'caracteristicas': [{'texto': 'Marca:', 'valor': 'Koblenz'}, {'texto': 'Artículo:', 'valor': 'Regulador/UPS'}, {'texto': 'Modelo:', 'valor': '5216 R'}, {'texto': 'Salida:', 'valor': 'Capacidad potencia 520 VA / 240 W | Tensión de salida nominal 120V distorsión ±10%'}, {'texto': 'Fase:', 'valor': 'Monofásica 120V'}, {'texto': 'Topología:', 'valor': 'Linea interactiva'}, {'texto': 'Frecuencia de salida en modo batería:', 'valor': '60 Hz ±1 Hz'}, {'texto': 'Conexiones de salida:', 'valor': '(3) NEMA 5-15R con protección de batería | (3) NEMA 5-15R sin protección de batería'}, {'texto': 'Tipo de forma de onda:', 'valor': 'Senoidal simulada'}, {'texto': 'Entrada:', 'valor': 'Voltaje 120V | Rango de voltaje 90 - 145 Vca | Frecuencia de entrada 60Hz '}, {'texto': 'Tipo de enchufe:', 'valor': 'NEMA 5-15P'}, {'texto': 'Longitud del cable:', 'valor': '1.5 metros'}, {'texto': 'Tipo de batería:', 'valor': 'Batería sellada de plomo ácido libre de mantenimiento a prueba de filtración'}, {'texto': 'Baterías pre-instaladas:', 'valor': '(1) 12V 4.5Ah'}, {'texto': 'Tiempo recarga:', 'valor': '4 horas al 90%'}, {'texto': 'Puerto de interfaz:', 'valor': 'USB'}, {'texto': 'Panel control:', 'valor': 'Pantalla LCD'}, {'texto': 'Protección:', 'valor': 'Supresión de picos 268 Joules | RJ-11'}, {'texto': 'Dimensiones:', 'valor': '29.1 cm x 13.9 cm x 10 cm'}]}] | F18: ['https://contenidos.exel.com.mx/ImagenesProductos/KBCREUAB004_zoom.jpg'] | G18: t | H18: 46085.479 | I18: 46085.479
A19: 00-4253-00-1 | B19: UPS Koblenz Online Doble Conversión 20KVA/18000W Ideal para Respaldo para Aplicaciones Críticas | C19: KOBLENZ | D19: UPS Koblenz Online Doble Conversión 20KVA/18000W Ideal para Respaldo para Aplicaciones Críticas | G19: t | H19: 46085.479 | I19: 46085.479
A20: 00-4257-00-2 | B20: UPS Koblenz 7522 USB/R 750VA/420W 10 Contactos 65 Minutos de Respaldo con una AIO | C20: KOBLENZ | D20: UPS Koblenz 7522 USB/R 750VA/420W 10 Contactos 65 Minutos de Respaldo con una AIO | G20: t | H20: 46085.479 | I20: 46085.479
A21: 00-4258-00-0 | B21: UPS Koblenz 9022 USB/R 900VA/450W 10 Contactos 76 Minutos de Respaldo con una AIO | C21: KOBLENZ | D21: UPS Koblenz 9022 USB/R 900VA/450W 10 Contactos 76 Minutos de Respaldo con una AIO | E21: [{'grupo': 'Características Generales:', 'caracteristicas': [{'texto': 'Marca:', 'valor': 'Koblenz'}, {'texto': 'Artículo:', 'valor': 'UPS/No Break'}, {'texto': 'Modelo:', 'valor': '9022-USB'}, {'texto': 'Tipo:', 'valor': 'Interactivo, onda cuasisenoidal'}, {'texto': 'Capacidad:', 'valor': '900 VA / 450 W'}, {'texto': 'Contactos:', 'valor': '5 respaldados, 5 con supresión de picos'}, {'texto': 'Respaldo:', 'valor': 'Hasta 76 minutos con una AIO'}, {'texto': 'Pantalla:', 'valor': 'LCD con indicador de Voltaje de entrada y salida, nivel de carga de la batería, nivel de carga del no break'}, {'texto': 'Puertos:', 'valor': 'USB de comunicación'}, {'texto': 'Batería:', 'valor': 'fácilmente desmontable 12V / 9 Ah'}, {'texto': 'Dimensiones:', 'valor': '39.2 cm x 26 cm x 14.5 cm'}, {'texto': 'Peso:', 'valor': '4.6 kg'}]}] | F21: ['https://contenidos.exel.com.mx/ImagenesProductos/KBCREUAB027_zoom.jpg'] | G21: t | H21: 46085.479 | I21: 46085.479
A22: 00-4260-00-6 | B22: UPS Koblenz 7516 USBR 750VA/450W 6 Contactos | C22: KOBLENZ | D22: UPS Línea Interactiva con Regulador de Voltaje integrado, ideal para la protección de equipos de escritorio. Factor de potencia 0.6. Protección contra sobre carga y corto circuito. Regulador de voltaje integrado (Altos y bajos) que permite la estabilización del voltaje. Arranque en frío modo batería. Indicadores LED para modo línea, batería, sobrecarga batería baja / reemplazo. Tiempo de respaldo 75 min. | E22: [{'grupo': 'Características Generales:', 'caracteristicas': [{'texto': 'Marca:', 'valor': 'Koblenz'}, {'texto': 'Artículo:', 'valor': 'UPS'}, {'texto': 'Modelo:', 'valor': '7516 USB/R'}, {'texto': 'Capacidad potencia:', 'valor': '750VA / 450W'}, {'texto': 'Fase:', 'valor': 'Monofásica 120V'}, {'texto': 'Topología:', 'valor': 'Línea interactiva'}, {'texto': 'Tiempo de transferencia:', 'valor': 'Típico 2-6 ms, 10 ms máximo'}, {'texto': 'Tensión de salida nominal:', 'valor': '120 Vca ±5%'}, {'texto': 'Frecuencia de salida en modo batería:', 'valor': '60 Hz ±1 Hz'}, {'texto': 'Tipo de forma de onda:', 'valor': 'Senoidal simulada PWM'}, {'texto': 'Conexiones de salida:', 'valor': '(4) NEMA 5-15R con protección de batería, (2) NEMA 5-15R sin protección de batería'}, {'texto': 'Voltaje de entrada:', 'valor': '120V - 127 V'}, {'texto': 'Rango de voltaje:', 'valor': '95 - 140 Vca'}, {'texto': 'Frecuencia de entrada:', 'valor': '60 Hz'}, {'texto': 'Tipo de clavija:', 'valor': 'NEMA 5-15P'}, {'texto': 'Tipo de batería:', 'valor': 'VRLA Batería sellada de plomo ácido libre de mantenimiento a prueba de filtración'}, {'texto': 'Baterías pre-instaladas:', 'valor': '(1) 12V 9 Ah'}, {'texto': 'Tiempo de Respaldo:', 'valor': '75 min'}, {'texto': 'Tiempo recarga:', 'valor': '4 hrs al 90%'}, {'texto': 'Baterías externas adicionales:', 'valor': 'No'}, {'texto': 'Puerto de interfaz:', 'valor': 'USB'}, {'texto': 'Tarjeta SNMP:', 'valor': 'No soportado'}, {'texto': 'Panel control:', 'valor': '(4) LED indicadores: Modo línea, modo batería, sobrecarga y batería baja/reemplazar'}, {'texto': 'Alarmas audibles:', 'valor': 'Modo de batería: sonido cada 10 segundos Batería baja: sonido cada segundo Sobrecarga: doble sonido cada 0.5 segundos Reemplazo de batería: sonido cada 2 segundos Falla: sonido contínuo'}, {'texto': 'Software:', 'valor': 'View Power'}, {'texto': 'Supresión de picos:', 'valor': 'Switch termomagnetico 7 A'}, {'texto': 'Ambiente operativo:', 'valor': '0-90% RH @ 0 - 40 ºC Sin Condensación'}, {'texto': 'Formato:', 'valor': 'Torre'}, {'texto': 'Gabinete:', 'valor': 'Plástico'}, {'texto': 'Dimensiones:', 'valor': '28.9 cm x 14.2 cm x 9.7 cm'}, {'texto': 'Peso:', 'valor': '4.25 kg'}, {'texto': 'Garantía:', 'valor': '3 Años'}, {'texto': 'Garantía de batería:', 'valor': '2 Años'}, {'texto': 'Certificaciones:', 'valor': 'NOM-001-SCFI-1993, ISO 9001:2015'}]}] | F22: ['https://contenidos.exel.com.mx/ImagenesProductos/KBCREUAB032_zoom.jpg'] | G22: t | H22: 46085.479 | I22: 46085.479
A23: 00-4263-00-0 | B23: UPS Koblenz 7616 USB/R 750VA/450W 6 Contactos (4/6) con Regulador Integrado | C23: KOBLENZ | D23: UPS Línea Interactiva con Regulador de Voltaje integrado, ideal para la protección de equipos de escritorio. Regulador de voltaje integrado (Altos y bajos) que permite la estabilización del voltaje. | E23: [{'grupo': 'Características Generales:', 'caracteristicas': [{'texto': 'Marca:', 'valor': 'Koblenz '}, {'texto': 'Artículo:', 'valor': 'UPS '}, {'texto': 'Capacidad:', 'valor': '750VA/450W'}, {'texto': 'Cantidad / Tipo de Salidas:', 'valor': '4 x NEMA 5-15R (con protección de batería y supresión de sobretensión) 2 x NEMA 5-15R (sin protección de batería con supresión de sobretensión)'}, {'texto': 'Otros: ', 'valor': 'con Regulador Integrado'}, {'texto': 'Fase:', 'valor': 'Monofásica 120V'}, {'texto': 'Topología:', 'valor': 'Línea interactiva'}, {'texto': 'Tiempo de transferencia:', 'valor': 'Típico 4 ms (Típico)'}, {'texto': 'Tensión de salida nominal:', 'valor': '-18% +18% 120 Vca ±5%'}, {'texto': 'Voltaje de entrada:', 'valor': '120 Vca ±5%'}, {'texto': 'Tipo de clavija:', 'valor': 'Interconstruido con clavija NEMA 5-15P'}, {'texto': 'Tipo de batería:', 'valor': 'VRLA Batería sellada de plomo ácido libre de mantenimiento a prueba de filtración'}, {'texto': 'Baterías pre-instaladas:', 'valor': '(1) 12V 9 Ah'}, {'texto': 'Panel control:', 'valor': '(4) LED indicadores: Modo línea, modo batería, sobrecarga y batería baja/ reemplazar'}, {'texto': 'Dimensiones:', 'valor': '28.7 cm x 14.2 cm x 10 cm'}, {'texto': 'Peso:', 'valor': '4.25 kg'}]}] | F23: ['https://contenidos.exel.com.mx/ImagenesProductos/KB/KBCREUAB039_zoom.jpg'] | G23: t | H23: 46085.479 | I23: 46085.479
A24: 00-5328-00-0 | B24: Supresor Pared Koblenz SS-1100 USB 100 Joules 7 Contactos/2 Puertos USB 2.4A LED | C24: KOBLENZ | D24: Supresor Pared Koblenz SS-1100 USB 100 Joules 7 Contactos/2 Puertos USB 2.4A LED | G24: t | H24: 46085.479 | I24: 46085.479
A25: 00-5333-00-0 | B25: Supresor Koblenz SS-550 USB 550 Joules 5 Contactos Aterrizados Switch On/Off 2 Puertos USB | C25: KOBLENZ | D25: El supresor de picos Koblenz verifica la entrada de energía constantemente y cuando detecta un valor de corriente o voltaje alto los componentes especialmente diseñados dentro del supresor lo recortan o amortiguan dando a sus equipos una protección instantánea | G25: t | H25: 46085.479 | I25: 46085.479
A26: 00-5340-00-5 | B26: Supresor Koblenz SS-420-C 420 Joules 6 Contactos Aterrizados Switch On/Off | C26: KOBLENZ | D26: El supresor de picos Koblenz verifica la entrada de energía constantemente y cuando detecta un valor de corriente o voltaje alto los componentes especialmente diseñados dentro del supresor lo recortan o amortiguan dando a sus equipos una protección instantánea | E26: [{'grupo': 'Características Generales:', 'caracteristicas': [{'texto': 'Marca:', 'valor': 'Koblenz'}, {'texto': 'Artículo:', 'valor': 'Supresor'}, {'texto': 'Modelo:', 'valor': 'SS-420-C'}, {'texto': 'Salida:', 'valor': 'Contactos aterrizados - (6) NEMA 5-15R'}, {'texto': 'Entrada:', 'valor': 'Voltaje 120V | Frecuencia de entrada 60 Hz'}, {'texto': 'Tipo de enchufe:', 'valor': 'NEMA 5-15P'}, {'texto': 'Longitud de cable:', 'valor': '0.45 metros'}, {'texto': 'Capacidad del disyuntor de entrada:', 'valor': '15 A'}, {'texto': 'Protección:', 'valor': 'Clasificación de energía de sobrecarga 420 Joules '}, {'texto': 'Switch:', 'valor': 'On / Off Iluminado con reset'}, {'texto': 'Material:', 'valor': 'Plástico'}]}] | F26: ['https://contenidos.exel.com.mx/ImagenesProductos/KBCSUPAB001_zoom.jpg'] | G26: t | H26: 46085.479 | I26: 46085.479
A27: 00-5342-00-1 | B27: Supresor Koblenz SS-460-C 460 Joules 6 Contactos Aterrizados Switch On/Off | C27: KOBLENZ | D27: El supresor de picos Koblenz verifica la entrada de energía constantemente y cuando detecta un valor de corriente o voltaje alto los componentes especialmente diseñados dentro del supresor lo recortan o amortiguan dando a sus equipos una protección instantánea | E27: [{'grupo': 'Características Generales:', 'caracteristicas': [{'texto': 'Marca:', 'valor': 'Koblenz'}, {'texto': 'Artículo:', 'valor': 'Supresor '}, {'texto': 'Modelo:', 'valor': 'SS-460-C'}, {'texto': 'Salida:', 'valor': 'Contactos aterrizados - (6) NEMA 5-15R'}, {'texto': 'Entrada:', 'valor': 'Voltaje 120V | Frecuencia de entrada 60 Hz'}, {'texto': 'Tipo de enchufe:', 'valor': 'NEMA 5-15P'}, {'texto': 'Longitud de cable:', 'valor': '0.45 metros'}, {'texto': 'Capacidad del disyuntor de entrada:', 'valor': '15 A'}, {'texto': 'Protección:', 'valor': 'Clasificación de energía de sobrecarga 460 Joules'}, {'texto': 'Switch:', 'valor': 'On / Off Iluminado con reset'}, {'texto': 'Material:', 'valor': 'Plástico'}]}] | F27: ['https://contenidos.exel.com.mx/ImagenesProductos/KBCSUPAB002_zoom.jpg'] | G27: t | H27: 46085.479 | I27: 46085.479
A28: 00-5347-00-0 | B28: Supresor Picos Koblenz PV-2500 D 2500 VA/2000W 6 Contactos Desconexión Automática con Alto o Bajo Voltaje | C28: KOBLENZ | D28: Supresor Picos Koblenz PV-2500 D 2500 VA/2000W 6 Contactos Desconexión Automática con Alto o Bajo Voltaje | G28: t | H28: 46085.479 | I28: 46085.479
A29: 00-5348-00-8 | B29: Supresor Picos Koblenz SS2000 USB 2000 Joules 6 Contactos 2 Puertos USB | C29: KOBLENZ | D29: Supresor Picos Koblenz SS2000 USB 2000 Joules 6 Contactos 2 Puertos USB | E29: [{'grupo': 'Características Generales:', 'caracteristicas': [{'texto': 'Marca:', 'valor': 'Koblenz'}, {'texto': 'Artículo:', 'valor': 'Supresor de picos'}, {'texto': 'Tipo:', 'valor': 'Multicontacto con Conexión USB'}, {'texto': 'Protección:', 'valor': '2,000 Joules '}, {'texto': 'Contactos:', 'valor': '6 Contactos giratorios NEMA 5-15R'}, {'texto': 'Puertos:', 'valor': '2 Puertos USB 2.4A 5Vcc '}, {'texto': 'Ruido:', 'valor': 'Filtro de ruido de 40dB'}, {'texto': 'Potencia:', 'valor': '15A'}, {'texto': 'Dimensiones:', 'valor': '23 cm x 11.8 cm x 6.2 cm'}, {'texto': 'Peso:', 'valor': '0.327 Kg'}]}] | F29: ['https://contenidos.exel.com.mx/ImagenesProductos/KBCSUPAB004_zoom.jpg', 'https://contenidos.exel.com.mx/ImagenesProductos/KBCSUPAB004_2_zoom.jpg', 'https://contenidos.exel.com.mx/ImagenesProductos/KBCSUPAB004_3_zoom.jpg'] | G29: t | H29: 46085.479 | I29: 46085.479
A30: 00-5360-00-3 | B30: Supresor Picos Koblenz SS-1100 USBAC 7 contactos 2 puertos USB 1100J | C30: KOBLENZ | D30: Supresor Picos Koblenz SS-1100 USBAC 7 contactos 2 puertos USB 1100J | E30: [{'grupo': 'Características Generales:', 'caracteristicas': [{'texto': 'Marca:', 'valor': 'Koblenz'}, {'texto': 'Artículo:', 'valor': 'Supresor '}, {'texto': 'Modelo:', 'valor': 'SS-1100 USBAC'}, {'texto': 'Multicontacto:', 'valor': 'Supresor de picos con conexión USB C'}, {'texto': 'Filtro de ruido:', 'valor': 'Ayuda a que al encender o usar algún aparato eléctrico el uso de energía de ese aparato no interrumpa o afecte la operación de los aparatos que están conectados al supresor'}, {'texto': 'Logo:', 'valor': '"K" LED frontal indica que el aparato está funcionando y la línea está protegida'}, {'texto': 'Contactos tipo NEMA 5-15R:', 'valor': '7'}, {'texto': 'Puerto USB tipo C de 35 Watts de carga rápida:', 'valor': '1'}, {'texto': 'Potencia:', 'valor': '15A'}, {'texto': 'Otros:', 'valor': 'Sin cables, se enchufa directo a la pared | Gabinete de plástico'}, {'texto': 'Color:', 'valor': 'Blanco'}, {'texto': 'Dimensiones con empaque:', 'valor': '23x19x7cm | Peso: 270 g '}, {'texto': 'Dimensiones sin empaque:', 'valor': '15.5x9.5x5.5cm | Peso: 217 g'}]}] | F30: ['https://contenidos.exel.com.mx/ImagenesProductos/KB/KBCSUPAB007_zoom.jpg'] | G30: t | H30: 46085.479 | I30: 46085.479
A31: 00-5361-00-1 | B31: MULTICONTACTO KOBLENZ SUPRESOR DE PICOS 2000 Joules 6 contactos guratorios 1 led 1 puertos USB A | C31: KOBLENZ | D31: MULTICONTACTO KOBLENZ SUPRESOR DE PICOS 2000 Joules 6 contactos guratorios 1 led 1 puertos USB A | E31: [{'grupo': 'Características Generales:', 'caracteristicas': [{'texto': 'Marca:', 'valor': 'Koblenz'}, {'texto': 'Artículo:', 'valor': 'Multicontacto'}, {'texto': 'Altura:', 'valor': '190 mm'}, {'texto': 'Profundidad:', 'valor': '40 mm'}, {'texto': 'Peso:', 'valor': '217 g'}, {'texto': 'Ancho:', 'valor': '90 mm'}, {'texto': 'Cantidad de puertos USB:', 'valor': '2'}, {'texto': 'Periodo de garantía:', 'valor': '3 Año(s)'}, {'texto': 'EMI/RFI, filtro de ruido:', 'valor': '40 dB'}, {'texto': 'Ancho del paquete:', 'valor': '118 mm'}, {'texto': 'Peso del paquete:', 'valor': '327 g'}, {'texto': 'Altura del paquete:', 'valor': '230 mm'}, {'texto': 'Tipo de salida AC:', 'valor': 'NEMA 5-15R'}, {'texto': 'Corriente nominal de salida:', 'valor': '15 A'}, {'texto': 'Carga por USB:', 'valor': 'Sí'}, {'texto': 'Cantidad de salidas AC:', 'valor': '6 Salidas'}, {'texto': 'Índice de aumento de energía:', 'valor': '2,000 Joules'}, {'texto': 'Materiales:', 'valor': 'Plástico'}, {'texto': 'Color del producto:', 'valor': 'Gris'}]}] | F31: ['https://contenidos.exel.com.mx/ImagenesProductos/KB/KBCSUPAB008_zoom.jpg'] | G31: t | H31: 46085.479 | I31: 46085.479
A32: 00-5369-00-4 | B32: Supresor Rojo Koblenz SS-300-C 300 Joules 6 Contactos Aterrizados Switch On/Off | C32: KOBLENZ | D32: Supresor Rojo Koblenz SS-300-C 300 Joules 6 Contactos Aterrizados Switch On/Off | E32: [{'grupo': 'Características Generales:', 'caracteristicas': [{'texto': 'Marca:', 'valor': 'Koblenz'}, {'texto': 'Artículo:', 'valor': 'Supresor'}, {'texto': 'Modelo:', 'valor': 'SS-300-C'}, {'texto': 'Color:', 'valor': 'Rojo'}, {'texto': 'Contactos:', 'valor': '6 Cotactos aterrizados'}, {'texto': 'Pprotección:', 'valor': '300 Joules'}, {'texto': 'Switch:', 'valor': 'Reset iluminado de 10 Amp'}, {'texto': 'Cable:', 'valor': '45cm'}, {'texto': 'Garantía:', 'valor': '1 año'}, {'texto': 'Dimensiones sin empaque:', 'valor': '12.5cm x 9.5cm x 3.5cm | Peso: 0.280 kg'}]}] | F32: ['https://contenidos.exel.com.mx/ImagenesProductos/KB/KBCSUPAB009_zoom.jpg', 'https://contenidos.exel.com.mx/ImagenesProductos/KB/KBCSUPAB009_2_zoom.jpg', 'https://contenidos.exel.com.mx/ImagenesProductos/KB/KBCSUPAB009_3_zoom.jpg', 'https://contenidos.exel.com.mx/ImagenesProductos/KB/KBCSUPAB009_4_zoom.jpg'] | G32: t | H32: 46085.479 | I32: 46085.479
A33: 0001 | B33: REGISTRADOR LEFORT 0001 CLASICO CARTA MARMOLEADO S/INDEX | C33: LEFORT | D33: REGISTRADOR LEFORT 0001 CLASICO CARTA MARMOLEADO S/INDEX | E33: [{'grupo': 'Especificaciones Generales', 'caracteristicas': [{'texto': 'Tamaño', 'valor': 'Carta'}, {'texto': 'Color', 'valor': 'Marmoleado'}]}] | G33: t | H33: 46085.479 | I33: 46085.479
A34: 0002 | B34: Registrador Lefort 0002 Clásico Oficio Marmoleado S/Index | C34: LEFORT | D34: Registrador Lefort 0002 Clásico Oficio Marmoleado S/Index | E34: [{'grupo': 'Especificaciones Generales', 'caracteristicas': [{'texto': 'Tamaño', 'valor': 'Oficio'}, {'texto': 'Color', 'valor': 'Marmoleado'}]}] | F34: ['https://contenidos.exel.com.mx/ImagenesProductos/LF/LFPREGAB010_zoom.jpg', 'https://contenidos.exel.com.mx/ImagenesProductos/LF/LFPREGAB010_2_zoom.jpg'] | G34: t | H34: 46085.479 | I34: 46085.479
A35: 0003 | B35: REGISTRADOR LEFORT MARMOLEADO TAMAÑO ESQUELA | C35: LEFORT | D35: REGISTRADOR LEFORT MARMOLEADO TAMAÑO ESQUELA | E35: [{'grupo': 'Especificaciones Generales', 'caracteristicas': [{'texto': 'Detalle:', 'valor': 'REGISTRADOR LEFORT MARMOLEADO TAMAÑO ESQUELA'}]}] | F35: ['https://contenidos.exel.com.mx/ImagenesProductos/LF/LFPREGAB011_zoom.jpg'] | G35: t | H35: 46085.479 | I35: 46085.479
A36: 0004 (REGISTRADOR LEFORT) | B36: Registrador Lefort Marmoleado Memorandum | C36: LEFORT | D36: Registrador Lefort Marmoleado Memorandum | E36: [{'grupo': 'Características Generales:', 'caracteristicas': [{'texto': 'Marca:', 'valor': 'Lefort '}, {'texto': 'Artículo:', 'valor': 'Registrador '}, {'texto': 'Tipo:', 'valor': 'Marmoleado '}]}] | F36: ['https://contenidos.exel.com.mx/ImagenesProductos/LF/LFPREGAB013_zoom.jpg'] | G36: t | H36: 46085.479 | I36: 46085.479
A37: 001297 | B37: CINTA KORES EPSON RC30 MORADO | C37: KORES | D37: <table border="0" cellpadding="0" cellspacing="0" width="776" style="border-collapse: collapse;width:582pt"> <tbody> <tr height="undefined" style="height:15.0pt"> <td height="20" class="xl65" width="776" style="height:15.0pt;width:582pt"> K cinta 459&nbsp;</td></tr></tbody></table> | E37: [{'grupo': 'Especificaciones Generales', 'caracteristicas': [{'texto': 'Detalle:', 'valor': 'Cinta Kores EpsonRC30 Morado'}]}] | F37: ['https://contenidos.exel.com.mx/ImagenesProductos/KRPCINAD046_zoom.jpg'] | G37: t | H37: 46085.479 | I37: 46085.479
A38: 001587 | B38: CINTA KORES P/BROTHER X10 MAQUINA ELECTRICA | C38: KORES | D38: <table border="0" cellpadding="0" cellspacing="0" width="776" style="border-collapse: collapse;width:582pt"> <tbody> <tr height="undefined" style="height:30.0pt"> <td height="40" class="xl65" width="776" style="height:30.0pt;width:582pt">Las cintas KORES son de una gran calidad debido a su intensidad y consistencia, f&#243;rmula&nbsp; de gran duraci&#243;n, resistentes y seguras.</td></tr></tbody></table> | E38: [{'grupo': 'Especificaciones Generales', 'caracteristicas': [{'texto': 'Detalle:', 'valor': 'Cinta Kores p /Brother X10 Maquina Electrica'}]}] | F38: ['https://contenidos.exel.com.mx/ImagenesProductos/KRPCINAD044_zoom.jpg'] | G38: t | H38: 46085.479 | I38: 46085.479
A39: 001907 | B39: CINTA P/CALCULADORA KORES NEGRO-ROJO 3.0CMS DIAMETRO | C39: KORES | D39: <table border="0" cellpadding="0" cellspacing="0" width="776" style="border-collapse: collapse;width:582pt"> <tbody> <tr height="undefined" style="height:15.0pt"> <td height="20" class="xl65" width="776" style="height:15.0pt;width:582pt"> K cinta para calculadora Secretary 255</td></tr></tbody></table> | E39: [{'grupo': 'Especificaciones Generales', 'caracteristicas': [{'texto': 'Detalle:', 'valor': 'Cinta P/Calculadora Kores'}, {'texto': 'Color:', 'valor': 'Negro-Rojo '}]}] | F39: ['https://contenidos.exel.com.mx/ImagenesProductos/KRPCINAD043_zoom.jpg'] | G39: t | H39: 46085.479 | I39: 46085.479
A40: 001R00600 | B40: Limpiador en Cinta Xerox 001R00600 60000 páginas | C40: XEROX | D40: Los artículos de mantenimiento de Xerox están diseñados para mantener su equipo Xerox operando de manera eficiente y para proporcionar la mejor calidad. | G40: t | H40: 46085.479 | I40: 46085.479
...

Sheet Hoja1
A1: cmarca
A2: 3M | B2: =VLOOKUP(A2,Hoja3!$B$2:$C$95,2,FALSE) -> https://images.icecat.biz/img/brand/thumb/206_d81d1d188e244538ab3082f8435acbd0.jpg
A3: ACCO | B3: =VLOOKUP(A3,Hoja3!$B$2:$C$95,2,FALSE) -> #N/A
A4: ACER | B4: =VLOOKUP(A4,Hoja3!$B$2:$C$95,2,FALSE) -> https://images.icecat.biz/img/brand/thumb/7_2e1091176d2d450eae2dce7506f1952f.jpg
A5: ACTECK | B5: =VLOOKUP(A5,Hoja3!$B$2:$C$95,2,FALSE) -> #N/A
A6: ACUACOLOR | B6: =VLOOKUP(A6,Hoja3!$B$2:$C$95,2,FALSE) -> #N/A
A7: ACUARELO | B7: =VLOOKUP(A7,Hoja3!$B$2:$C$95,2,FALSE) -> #N/A
A8: ADATA | B8: =VLOOKUP(A8,Hoja3!$B$2:$C$95,2,FALSE) -> https://images.icecat.biz/img/brand/thumb/2634_2a848859d95b45c98590f1c44384958e.jpg
A9: ADESSO | B9: =VLOOKUP(A9,Hoja3!$B$2:$C$95,2,FALSE) -> #N/A
A10: AINK | B10: =VLOOKUP(A10,Hoja3!$B$2:$C$95,2,FALSE) -> #N/A
A11: ALFRA | B11: =VLOOKUP(A11,Hoja3!$B$2:$C$95,2,FALSE) -> #N/A
A12: AMAZON | B12: =VLOOKUP(A12,Hoja3!$B$2:$C$95,2,FALSE) -> #N/A
A13: AMD | B13: =VLOOKUP(A13,Hoja3!$B$2:$C$95,2,FALSE) -> #N/A
... A199: ZOTAC | B199: =VLOOKUP(A199,Hoja3!$B$2:$C$95,2,FALSE) -> #N/A

Sheet Hoja2
A1: cmarca | B1: cimagen
A2: Swingline
A3: -
A4: 3 En 1
A5: 3I Corporation
A6: 3M | B6: https://images.icecat.biz/img/brand/thumb/206_d81d1d188e244538ab3082f8435acbd0.jpg
A7: 3M | B7: https://inishop.com/thumbs/SUP723.jpg
A8: 3M | B8: https://inishop.com/img/brand/thumb/804_0475cea0b61e4842aa61baa9c12edea7.jpg
A9: 3Nstar | B9: https://inishop.com/img/brand/thumb/18611_2e1846547a7845eaacc3d381f61f7e01.jpg
A10: 4Gamers
A11: Abell
A12: Abloy
A13: Absormex
A14: Accesspro | B14: https://inishop.com/img/brand/thumb/19849_04c0e1122efd485baf68c1182d5ebfca.jpg
A15: Accesspro
A16: Accesspro Industrial
A17: Acco
A18: Acer | B18: https://images.icecat.biz/img/brand/thumb/7_2e1091176d2d450eae2dce7506f1952f.jpg
A19: Acme
A20: Acteck
A21: Acti
A22: Actisense
A23: Acuacolor
A24: Acuarelo
A25: Adata | B25: https://images.icecat.biz/img/brand/thumb/2634_2a848859d95b45c98590f1c44384958e.jpg
A26: Adata | B26: https://images.icecat.biz/img/brand/thumb/32301_3243df0daeb740f998efd0a01bc129bb.jpg
A27: Ademco (Honeywell)
A28: Adesso | B28: https://inishop.com/img/brand/thumb/2817_db5fa942fc2640078996fc400d4fd629.jpg
A29: Adex
A30: Advancetec Industries Inc
A31: Aea
A32: Aerocool | B32: https://images.icecat.biz/img/brand/thumb/1935_406c04e90f78451e8cdd4a6a2a4c0e6f.jpg
A33: Afore
A34: Aink
A35: Airmar
A36: Airx
A37: Ajax
A38: Akubela
A39: Akuvox
A40: Alarm Controls-Assa Abloy
...

Sheet Hoja3
A1: cmarca | C1: cimagen
A2: 3M | B2: =UPPER(A2) -> 3M | C2: https://images.icecat.biz/img/brand/thumb/206_d81d1d188e244538ab3082f8435acbd0.jpg
A3: Acer | B3: =UPPER(A3) -> ACER | C3: https://images.icecat.biz/img/brand/thumb/7_2e1091176d2d450eae2dce7506f1952f.jpg
A4: Adata | B4: =UPPER(A4) -> ADATA | C4: https://images.icecat.biz/img/brand/thumb/2634_2a848859d95b45c98590f1c44384958e.jpg
A5: Adata | B5: =UPPER(A5) -> ADATA | C5: https://images.icecat.biz/img/brand/thumb/32301_3243df0daeb740f998efd0a01bc129bb.jpg
A6: Aerocool | B6: =UPPER(A6) -> AEROCOOL | C6: https://images.icecat.biz/img/brand/thumb/1935_406c04e90f78451e8cdd4a6a2a4c0e6f.jpg
A7: Allied Telesis | B7: =UPPER(A7) -> ALLIED TELESIS | C7: https://images.icecat.biz/img/brand/thumb/49_8e89cb7fac62454a81797ce1e528cb76.jpg
A8: Aoc | B8: =UPPER(A8) -> AOC | C8: https://images.icecat.biz/img/brand/thumb/1718_472c0e4c9d01478d872b6401f8d04669.jpg
A9: Apc | B9: =UPPER(A9) -> APC | C9: https://images.icecat.biz/img/brand/thumb/33_68f38ab5dafc49faaa807fd70d2b6d33.jpg
A10: Asus | B10: =UPPER(A10) -> ASUS | C10: https://images.icecat.biz/img/brand/thumb/161_0457b539b0334f679d065c1176fa11ab.jpg
A11: ASUS | B11: =UPPER(A11) -> ASUS | C11: https://images.icecat.biz/img/brand/thumb/161_0457b539b0334f679d065c1176fa11ab.jpg
A12: ASUS | B12: =UPPER(A12) -> ASUS | C12: https://images.icecat.biz/img/brand/thumb/739_aa2abbe6aded43bdabf4df493efecca8.jpg
A13: Aten | B13: =UPPER(A13) -> ATEN | C13: https://images.icecat.biz/img/brand/thumb/2823_cbe873306b3c4c08b1ade01733975f88.jpg
... A95: Turtle Beach | B95: =UPPER(A95) -> TURTLE BEACH | C95: https://images.icecat.biz/img/brand/thumb/3256_5c751e86992a4aaba8abfc1c34493cf9.jpg
